<?xml version="1.0" encoding="utf-8"?>
<robot name="mg400">
  
  <link name="base_link">
    <visual>
      <origin xyz="0 0 0" rpy="0 0 0"/>
      <geometry>
        <mesh filename="package://mg400_description/meshes/base_link.STL"/>
      </geometry>
      <material name="white"><color rgba="1 1 1 1"/></material>
    </visual>
    <collision>
      <origin xyz="0 0 0" rpy="0 0 0"/>
      <geometry>
        <mesh filename="package://mg400_description/meshes/base_link.STL"/>
      </geometry>
    </collision>
  </link>

  <link name="link1">
    <visual>
      <origin xyz="0 0 0" rpy="0 0 0"/>
      <geometry>
        <mesh filename="package://mg400_description/meshes/link1.STL"/>
      </geometry>
      <material name="white"><color rgba="1 1 1 1"/></material>
    </visual>
    <collision>
      <origin xyz="0 0 0" rpy="0 0 0"/>
      <geometry>
        <mesh filename="package://mg400_description/meshes/link1.STL"/>
      </geometry>
    </collision>
  </link>

  <joint name="j1" type="revolute">
    <origin xyz="-0.005 0 0.109" rpy="0 0 0"/>
    <parent link="base_link"/>
    <child link="link1"/>
    <axis xyz="0 0 1"/>
    <limit lower="-2.792" upper="2.792" effort="10" velocity="5.585"/>
  </joint>

  <link name="link2">
    <visual>
      <origin xyz="0 0 0" rpy="0 0 0"/>
      <geometry>
        <mesh filename="package://mg400_description/meshes/link2_1.STL"/>
      </geometry>
      <material name="white"><color rgba="1 1 1 1"/></material>
    </visual>
    <collision>
      <origin xyz="0 0 0" rpy="0 0 0"/>
      <geometry>
        <mesh filename="package://mg400_description/meshes/link2_1.STL"/>
      </geometry>
    </collision>
  </link>

  <joint name="j2" type="revolute">
    <origin xyz="0.0435 -0.0358 0.119" rpy="0 0 0"/>
    <parent link="link1"/>
    <child link="link2"/>
    <axis xyz="0 1 0"/>
    <limit lower="-0.436" upper="1.484" effort="10" velocity="5.585"/>
  </joint>

  <link name="link3">
    <visual>
      <origin xyz="0 0 0" rpy="0 0 0"/>
      <geometry>
        <mesh filename="package://mg400_description/meshes/link3_1.STL"/>
      </geometry>
      <material name="white"><color rgba="1 1 1 1"/></material>
    </visual>
    <collision>
      <origin xyz="0 0 0" rpy="0 0 0"/>
      <geometry>
        <mesh filename="package://mg400_description/meshes/link3_1.STL"/>
      </geometry>
    </collision>
  </link>

  <joint name="j3" type="revolute">
    <origin xyz="-0.001 0.0358 0.175" rpy="0 0 0"/>
    <parent link="link2"/>
    <child link="link3"/>
    <axis xyz="0 1 0"/>
    <limit lower="-0.436" upper="0.873" effort="10" velocity="5.585"/>
  </joint>

  <link name="link4">
    <visual>
      <origin xyz="0 0 0" rpy="0 0 0"/>
      <geometry>
        <mesh filename="package://mg400_description/meshes/link4_1.STL"/>
      </geometry>
      <material name="white"><color rgba="1 1 1 1"/></material>
    </visual>
    <collision>
      <origin xyz="0 0 0" rpy="0 0 0"/>
      <geometry>
        <mesh filename="package://mg400_description/meshes/link4_1.STL"/>
      </geometry>
    </collision>
  </link>

  <joint name="j3_to_link4" type="revolute">
    <origin xyz="0.175 -0.017 0.003" rpy="0 0 0"/>
    <parent link="link3"/>
    <child link="link4"/>
    <axis xyz="0 1 0"/>
    <limit lower="-3.14" upper="3.14" effort="10" velocity="5.0"/>
  </joint>

  <link name="link5">
    <visual>
      <origin xyz="0 0 0" rpy="0 0 0"/>
      <geometry>
        <mesh filename="package://mg400_description/meshes/link5.STL"/>
      </geometry>
      <material name="white"><color rgba="1 1 1 1"/></material>
    </visual>
    <collision>
      <origin xyz="0 0 0" rpy="0 0 0"/>
      <geometry>
        <mesh filename="package://mg400_description/meshes/link5.STL"/>
      </geometry>
    </collision>
  </link>

  <joint name="j4" type="revolute">
    <origin xyz="0.066 0.017 0.031" rpy="0 0 0"/>
    <parent link="link4"/>
    <child link="link5"/>
    <axis xyz="0 0 1"/>
    <limit lower="-3.142" upper="3.142" effort="10" velocity="8.378"/>
  </joint>

  <link name="tool0"/>
  
  <joint name="link5_to_tool0" type="fixed">
    <origin xyz="0 0 -0.07" rpy="0 0 0"/>
    <parent link="link5"/>
    <child link="tool0"/>
  </joint>

</robot>